Workbook

Sheet README
A1: PII / PHI Enterprise Entity Policy Taxonomy
A2: Candidate taxonomy for the Document Intelligence detection pipeline — MUST_HAVE / NICE_TO_HAVE / DROP
A4: SCOPE & METHOD
A5: - This workbook was built directly from the brief supplied in this engagement. No existing teammate workbook/candidate taxonomy file was attached to this conversation, so there was no prior candidate taxonomy to validate against — this workbook is the first-pass candidate itself and should be reviewed by an SME before production use (see 'Reviewed Status' column).
A6: - Regulatory citations use only the official source URLs supplied in the brief (HHS/HIPAA, EUR-Lex/GDPR, PCI SSC, NIST, FTC, MeitY/India DPDP). Where a precise citation was not present in the supplied source set (e.g., GDPR Art. 10 on criminal-offense data, 42 CFR Part 2, US FCRA, IRS Publication 4812), that gap is flagged explicitly in the Notes column and the row's Regulation Type is marked INFERENCE or RISK-BASED RECOMMENDATION rather than REGULATORY REQUIREMENT.
A7: - No company/client policy document was supplied for this engagement. Every row's Company Policy column reads 'Company policy evidence not supplied.' as instructed — no internal policy has been invented.
A8: - 27 document types across Healthcare, Financial, Corporate/HR, Legal/Business, Identity, Security/Technical, and Generic categories are covered, per the brief's required scope.
A10: REGULATION TYPE LEGEND (used in Master_Entity_Policy, column K context)
A11: - REGULATORY REQUIREMENT: a binding legal obligation under the cited law/regulation, for the stated jurisdiction.
A12: - STANDARD/CONTROL: an industry standard or risk-management framework (e.g., PCI DSS, NIST SP 800-122) rather than a statute.
A13: - RISK-BASED RECOMMENDATION: not explicitly enumerated by a cited regulation in the supplied source set; classified using breach-impact reasoning.
A14: - INFERENCE: the closest available citation in the supplied source set does not squarely cover this entity (the precise citation is named in Rationale/Notes); verify independently before relying on it.
... A33: - See the accompanying change summary for full before/after counts and items flagged for SME review.

Sheet Master_Entity_Policy
A1: Document Type | B1: Business Workflow | C1: Entity | D1: Canonical Entity Type | E1: Category | F1: Data Type (PII/PHI/Financial/Payment/Credential/Other) | G1: Priority | H1: Risk Level | I1: Threat if Exposed | J1: Regulation | K1: Regulation Section / Article / Requirement | L1: Jurisdiction | M1: Evidence URL | N1: Classification Basis | O1: Evidence Type | P1: Confidence in Classification
A2: Medical Record / Clinical Note | B2: Ongoing clinical documentation of a patient's encounters, diagnoses, and treatment to support continuity of care. | C2: Full Name / Person Name | D2: Full Name / Person Name | E2: Direct Identifier | F2: PII | G2: MUST_HAVE | H2: CRITICAL | I2: Re-identifies an individual's health record; enables medical-identity theft and targeted harassment. | J2: HIPAA Privacy Rule | K2: 45 CFR 164.514(b)(2) — Safe Harbor identifier list | L2: United States — HIPAA covered entities & business associates | M2: https://www.hhs.gov/hipaa/for-professionals/special-topics/de-identification/index.html | N2: REGULATION | O2: Explicitly protected identifier | P2: MEDIUM
A3: Medical Record / Clinical Note | B3: Ongoing clinical documentation of a patient's encounters, diagnoses, and treatment to support continuity of care. | C3: Date of Birth | D3: Date of Birth | E3: Direct Identifier | F3: PII | G3: MUST_HAVE | H3: HIGH | I3: HIPAA Safe Harbor identifier; strengthens patient re-identification when combined with other fields. | J3: HIPAA Privacy Rule | K3: 45 CFR 164.514(b)(2) — Safe Harbor identifier list | L3: United States — HIPAA covered entities & business associates | M3: https://www.hhs.gov/hipaa/for-professionals/special-topics/de-identification/index.html | N3: REGULATION | O3: Explicitly protected identifier | P3: MEDIUM
A4: Medical Record / Clinical Note | B4: Ongoing clinical documentation of a patient's encounters, diagnoses, and treatment to support continuity of care. | C4: Medical Record Number (MRN) | D4: Medical Record Number (MRN) | E4: Direct Identifier | F4: PHI | G4: MUST_HAVE | H4: CRITICAL | I4: Directly links an individual to their entire clinical history; enables medical-identity theft and insurance fraud. | J4: HIPAA Privacy Rule | K4: 45 CFR 164.514(b)(2)(I) — Medical record numbers | L4: United States — HIPAA covered entities | M4: https://www.hhs.gov/hipaa/for-professionals/special-topics/de-identification/index.html | N4: REGULATION | O4: PHI / health information | P4: HIGH
A5: Medical Record / Clinical Note | B5: Ongoing clinical documentation of a patient's encounters, diagnoses, and treatment to support continuity of care. | C5: Street / Mailing Address | D5: Street / Mailing Address | E5: Direct Identifier | F5: PII | G5: MUST_HAVE | H5: HIGH | I5: HIPAA Safe Harbor identifier; discloses where a patient lives, raising both privacy and physical-safety risk. | J5: HIPAA Privacy Rule | K5: 45 CFR 164.514(b)(2) — Safe Harbor identifier list | L5: United States — HIPAA covered entities & business associates | M5: https://www.hhs.gov/hipaa/for-professionals/special-topics/de-identification/index.html | N5: REGULATION | O5: Explicitly protected identifier | P5: MEDIUM
A6: Medical Record / Clinical Note | B6: Ongoing clinical documentation of a patient's encounters, diagnoses, and treatment to support continuity of care. | C6: Phone Number | D6: Phone Number | E6: Direct Identifier | F6: PII | G6: MUST_HAVE | H6: MEDIUM | I6: HIPAA Safe Harbor identifier; enables phishing/social engineering against a patient. | J6: HIPAA Privacy Rule | K6: 45 CFR 164.514(b)(2) — Safe Harbor identifier list | L6: United States — HIPAA covered entities & business associates | M6: https://www.hhs.gov/hipaa/for-professionals/special-topics/de-identification/index.html | N6: REGULATION | O6: Explicitly protected identifier | P6: MEDIUM
A7: Medical Record / Clinical Note | B7: Ongoing clinical documentation of a patient's encounters, diagnoses, and treatment to support continuity of care. | C7: Diagnosis / Medical Condition | D7: Diagnosis / Medical Condition | E7: Health/Clinical Data | F7: PHI | G7: MUST_HAVE | H7: CRITICAL | I7: Discrimination, stigmatization, employment/insurance harm, and medical-privacy harm if disclosed. | J7: HIPAA Privacy Rule | K7: 45 CFR 160.103 — Protected Health Information definition | L7: United States — HIPAA covered entities | M7: https://www.hhs.gov/hipaa/for-professionals/special-topics/de-identification/index.html | N7: REGULATION | O7: PHI / health information | P7: HIGH
A8: Medical Record / Clinical Note | B8: Ongoing clinical documentation of a patient's encounters, diagnoses, and treatment to support continuity of care. | C8: Procedure Code / Description | D8: Procedure Code / Description | E8: Health/Clinical Data | F8: PHI | G8: NICE_TO_HAVE | H8: MEDIUM | I8: Discloses treatment history; can imply a condition (re-identification risk) and support insurance fraud. | J8: HIPAA Privacy Rule | K8: 45 CFR 160.103 — PHI definition | L8: United States — HIPAA covered entities | M8: https://www.hhs.gov/hipaa/for-professionals/special-topics/de-identification/index.html | N8: REGULATION | O8: PHI / health information | P8: MEDIUM
A9: Medical Record / Clinical Note | B9: Ongoing clinical documentation of a patient's encounters, diagnoses, and treatment to support continuity of care. | C9: Medication / Prescription Detail | D9: Medication / Prescription Detail | E9: Health/Clinical Data | F9: PHI | G9: MUST_HAVE | H9: HIGH | I9: Can reveal a sensitive condition by inference (e.g., psychiatric, HIV, oncology drugs); enables prescription fraud. | J9: HIPAA Privacy Rule | K9: 45 CFR 160.103 — PHI definition | L9: United States — HIPAA covered entities | M9: https://www.hhs.gov/hipaa/for-professionals/special-topics/de-identification/index.html | N9: REGULATION | O9: PHI / health information | P9: HIGH
A10: Medical Record / Clinical Note | B10: Ongoing clinical documentation of a patient's encounters, diagnoses, and treatment to support continuity of care. | C10: Clinical Notes / Narrative | D10: Clinical Notes / Narrative | E10: Health/Clinical Data | F10: PHI | G10: MUST_HAVE | H10: CRITICAL | I10: Free text frequently contains multiple PHI elements at once (identity + diagnosis + history); high aggregate breach impact. | J10: HIPAA Privacy Rule | K10: 45 CFR 160.103 — PHI definition | L10: United States — HIPAA covered entities | M10: https://www.hhs.gov/hipaa/for-professionals/special-topics/de-identification/index.html | N10: REGULATION | O10: PHI / health information | P10: HIGH
A11: Medical Record / Clinical Note | B11: Ongoing clinical documentation of a patient's encounters, diagnoses, and treatment to support continuity of care. | C11: Allergy Information | D11: Allergy Information | E11: Health/Clinical Data | F11: PHI | G11: NICE_TO_HAVE | H11: MEDIUM | I11: Reveals health information; misuse risk lower than diagnosis but still privacy-sensitive. | J11: HIPAA Privacy Rule | K11: 45 CFR 160.103 — PHI definition | L11: United States — HIPAA covered entities | M11: https://www.hhs.gov/hipaa/for-professionals/special-topics/de-identification/index.html | N11: REGULATION | O11: PHI / health information | P11: MEDIUM
A12: Medical Record / Clinical Note | B12: Ongoing clinical documentation of a patient's encounters, diagnoses, and treatment to support continuity of care. | C12: Treating Provider Name / NPI Number | D12: Treating Provider Name / NPI Number | E12: Direct Identifier | F12: PHI | G12: NICE_TO_HAVE | H12: MEDIUM | I12: Discloses the treating clinician; can support social engineering against the practice, lower risk to the patient directly. | J12: HIPAA Privacy Rule | K12: 45 CFR 164.514(b)(2) — related identifiers | L12: United States — HIPAA covered entities | M12: https://www.hhs.gov/hipaa/for-professionals/special-topics/de-identification/index.html | N12: REGULATION | O12: PHI / health information | P12: MEDIUM
... A23: Lab Report / Pathology Report | B23: Laboratory or pathology testing and result reporting to support diagnosis and treatment decisions. | C23: Admission / Discharge / Service Date | D23: Admission / Discharge / Service Date | E23: Direct Identifier | F23: PHI | G23: MUST_HAVE | H23: MEDIUM | I23: Enables re-identification when correlated with public event data (e.g., accident reports); listed HIPAA identifier. | J23: HIPAA Privacy Rule | K23: 45 CFR 164.514(b)(2)(I) — All elements of dates related to an individual | L23: United States — HIPAA covered entities | M23: https://www.hhs.gov/hipaa/for-professionals/special-topics/de-identification/index.html | N23: REGULATION | O23: PHI / health information | P23: HIGH
A24: Lab Report / Pathology Report | B24: Laboratory or pathology testing and result reporting to support diagnosis and treatment decisions. | C24: Medical Equipment/Instrument Serial Number | D24: Medical Equipment/Instrument Serial Number | E24: Administrative/Structural Metadata | F24: Other | G24: DROP | I24: None — identifies a machine/asset, not a person; occasionally relevant to biomedical-device recall workflows but not a privacy target. | J24: N/A | K24: N/A | L24: N/A | N24: CONTEXTUAL | O24: Low-value technical field | P24: MEDIUM
A25: Prescription | B25: Prescribing and dispensing of medication to a patient. | C25: Full Name / Person Name | D25: Full Name / Person Name | E25: Direct Identifier | F25: PII | G25: MUST_HAVE | H25: CRITICAL | I25: Re-identifies an individual's health record; enables medical-identity theft and targeted harassment. | J25: HIPAA Privacy Rule | K25: 45 CFR 164.514(b)(2) — Safe Harbor identifier list | L25: United States — HIPAA covered entities & business associates | M25: https://www.hhs.gov/hipaa/for-professionals/special-topics/de-identification/index.html | N25: REGULATION | O25: Explicitly protected identifier | P25: MEDIUM
A26: Prescription | B26: Prescribing and dispensing of medication to a patient. | C26: Date of Birth | D26: Date of Birth | E26: Direct Identifier | F26: PII | G26: MUST_HAVE | H26: HIGH | I26: HIPAA Safe Harbor identifier; strengthens patient re-identification when combined with other fields. | J26: HIPAA Privacy Rule | K26: 45 CFR 164.514(b)(2) — Safe Harbor identifier list | L26: United States — HIPAA covered entities & business associates | M26: https://www.hhs.gov/hipaa/for-professionals/special-topics/de-identification/index.html | N26: REGULATION | O26: Explicitly protected identifier | P26: MEDIUM
A27: Prescription | B27: Prescribing and dispensing of medication to a patient. | C27: Street / Mailing Address | D27: Street / Mailing Address | E27: Direct Identifier | F27: PII | G27: MUST_HAVE | H27: HIGH | I27: HIPAA Safe Harbor identifier; discloses where a patient lives, raising both privacy and physical-safety risk. | J27: HIPAA Privacy Rule | K27: 45 CFR 164.514(b)(2) — Safe Harbor identifier list | L27: United States — HIPAA covered entities & business associates | M27: https://www.hhs.gov/hipaa/for-professionals/special-topics/de-identification/index.html | N27: REGULATION | O27: Explicitly protected identifier | P27: MEDIUM
A28: Prescription | B28: Prescribing and dispensing of medication to a patient. | C28: Medication / Prescription Detail | D28: Medication / Prescription Detail | E28: Health/Clinical Data | F28: PHI | G28: MUST_HAVE | H28: HIGH | I28: Can reveal a sensitive condition by inference (e.g., psychiatric, HIV, oncology drugs); enables prescription fraud. | J28: HIPAA Privacy Rule | K28: 45 CFR 160.103 — PHI definition | L28: United States — HIPAA covered entities | M28: https://www.hhs.gov/hipaa/for-professionals/special-topics/de-identification/index.html | N28: REGULATION | O28: PHI / health information | P28: HIGH
A29: Prescription | B29: Prescribing and dispensing of medication to a patient. | C29: Treating Provider Name / NPI Number | D29: Treating Provider Name / NPI Number | E29: Direct Identifier | F29: PHI | G29: NICE_TO_HAVE | H29: MEDIUM | I29: Discloses the treating clinician; can support social engineering against the practice, lower risk to the patient directly. | J29: HIPAA Privacy Rule | K29: 45 CFR 164.514(b)(2) — related identifiers | L29: United States — HIPAA covered entities | M29: https://www.hhs.gov/hipaa/for-professionals/special-topics/de-identification/index.html | N29: REGULATION | O29: PHI / health information | P29: MEDIUM
A30: Prescription | B30: Prescribing and dispensing of medication to a patient. | C30: Medical Record Number (MRN) | D30: Medical Record Number (MRN) | E30: Direct Identifier | F30: PHI | G30: MUST_HAVE | H30: CRITICAL | I30: Directly links an individual to their entire clinical history; enables medical-identity theft and insurance fraud. | J30: HIPAA Privacy Rule | K30: 45 CFR 164.514(b)(2)(I) — Medical record numbers | L30: United States — HIPAA covered entities | M30: https://www.hhs.gov/hipaa/for-professionals/special-topics/de-identification/index.html | N30: REGULATION | O30: PHI / health information | P30: HIGH
A31: Prescription | B31: Prescribing and dispensing of medication to a patient. | C31: Signature | D31: Signature | E31: Direct Identifier | F31: PII | G31: NICE_TO_HAVE | H31: MEDIUM | I31: Enables forgery of authorization for treatment or disclosure. | J31: HIPAA Privacy Rule | K31: 45 CFR 164.514(b)(2) — Safe Harbor identifier list | L31: United States — HIPAA covered entities & business associates | M31: https://www.hhs.gov/hipaa/for-professionals/special-topics/de-identification/index.html | N31: REGULATION | O31: Explicitly protected identifier | P31: MEDIUM
A32: Prescription | B32: Prescribing and dispensing of medication to a patient. | C32: Health Insurance Policy Number | D32: Health Insurance Policy Number | E32: Direct Identifier | F32: PHI | G32: MUST_HAVE | H32: HIGH | I32: Enables fraudulent insurance claims and unauthorized access to coverage details. | J32: HIPAA Privacy Rule | K32: 45 CFR 164.514(b)(2)(I) — Health plan beneficiary numbers | L32: United States — HIPAA covered entities | M32: https://www.hhs.gov/hipaa/for-professionals/special-topics/de-identification/index.html | N32: REGULATION | O32: PHI / health information | P32: HIGH
A33: Discharge Summary | B33: Summary of a patient's hospital stay, treatment, and follow-up plan at the point of discharge. | C33: Full Name / Person Name | D33: Full Name / Person Name | E33: Direct Identifier | F33: PII | G33: MUST_HAVE | H33: CRITICAL | I33: Re-identifies an individual's health record; enables medical-identity theft and targeted harassment. | J33: HIPAA Privacy Rule | K33: 45 CFR 164.514(b)(2) — Safe Harbor identifier list | L33: United States — HIPAA covered entities & business associates | M33: https://www.hhs.gov/hipaa/for-professionals/special-topics/de-identification/index.html | N33: REGULATION | O33: Explicitly protected identifier | P33: MEDIUM
A34: Discharge Summary | B34: Summary of a patient's hospital stay, treatment, and follow-up plan at the point of discharge. | C34: Date of Birth | D34: Date of Birth | E34: Direct Identifier | F34: PII | G34: MUST_HAVE | H34: HIGH | I34: HIPAA Safe Harbor identifier; strengthens patient re-identification when combined with other fields. | J34: HIPAA Privacy Rule | K34: 45 CFR 164.514(b)(2) — Safe Harbor identifier list | L34: United States — HIPAA covered entities & business associates | M34: https://www.hhs.gov/hipaa/for-professionals/special-topics/de-identification/index.html | N34: REGULATION | O34: Explicitly protected identifier | P34: MEDIUM
A35: Discharge Summary | B35: Summary of a patient's hospital stay, treatment, and follow-up plan at the point of discharge. | C35: Medical Record Number (MRN) | D35: Medical Record Number (MRN) | E35: Direct Identifier | F35: PHI | G35: MUST_HAVE | H35: CRITICAL | I35: Directly links an individual to their entire clinical history; enables medical-identity theft and insurance fraud. | J35: HIPAA Privacy Rule | K35: 45 CFR 164.514(b)(2)(I) — Medical record numbers | L35: United States — HIPAA covered entities | M35: https://www.hhs.gov/hipaa/for-professionals/special-topics/de-identification/index.html | N35: REGULATION | O35: PHI / health information | P35: HIGH
A36: Discharge Summary | B36: Summary of a patient's hospital stay, treatment, and follow-up plan at the point of discharge. | C36: Diagnosis / Medical Condition | D36: Diagnosis / Medical Condition | E36: Health/Clinical Data | F36: PHI | G36: MUST_HAVE | H36: CRITICAL | I36: Discrimination, stigmatization, employment/insurance harm, and medical-privacy harm if disclosed. | J36: HIPAA Privacy Rule | K36: 45 CFR 160.103 — Protected Health Information definition | L36: United States — HIPAA covered entities | M36: https://www.hhs.gov/hipaa/for-professionals/special-topics/de-identification/index.html | N36: REGULATION | O36: PHI / health information | P36: HIGH
... A49: Imaging / Radiology Report | B49: Interpretation and reporting of diagnostic imaging studies (X-ray, CT, MRI, ultrasound). | C49: Admission / Discharge / Service Date | D49: Admission / Discharge / Service Date | E49: Direct Identifier | F49: PHI | G49: MUST_HAVE | H49: MEDIUM | I49: Enables re-identification when correlated with public event data (e.g., accident reports); listed HIPAA identifier. | J49: HIPAA Privacy Rule | K49: 45 CFR 164.514(b)(2)(I) — All elements of dates related to an individual | L49: United States — HIPAA covered entities | M49: https://www.hhs.gov/hipaa/for-professionals/special-topics/de-identification/index.html | N49: REGULATION | O49: PHI / health information | P49: HIGH
A50: Imaging / Radiology Report | B50: Interpretation and reporting of diagnostic imaging studies (X-ray, CT, MRI, ultrasound). | C50: CT Number / Imaging Technical Parameter | D50: CT Number / Imaging Technical Parameter | E50: Administrative/Structural Metadata | F50: Other | G50: DROP | I50: None — a physical measurement/scanner calibration value, not a personal identifier or health-status disclosure. | J50: N/A | K50: N/A | L50: N/A | N50: CONTEXTUAL | O50: Low-value technical field | P50: HIGH
A51: Imaging / Radiology Report | B51: Interpretation and reporting of diagnostic imaging studies (X-ray, CT, MRI, ultrasound). | C51: Medical Equipment/Instrument Serial Number | D51: Medical Equipment/Instrument Serial Number | E51: Administrative/Structural Metadata | F51: Other | G51: DROP | I51: None — identifies a machine/asset, not a person; occasionally relevant to biomedical-device recall workflows but not a privacy target. | J51: N/A | K51: N/A | L51: N/A | N51: CONTEXTUAL | O51: Low-value technical field | P51: MEDIUM
A52: Patient Registration / Referral | B52: Intake and registration of a new patient, or referral of a patient between providers. | C52: Full Name / Person Name | D52: Full Name / Person Name | E52: Direct Identifier | F52: PII | G52: MUST_HAVE | H52: CRITICAL | I52: Re-identifies an individual's health record; enables medical-identity theft and targeted harassment. | J52: HIPAA Privacy Rule | K52: 45 CFR 164.514(b)(2) — Safe Harbor identifier list | L52: United States — HIPAA covered entities & business associates | M52: https://www.hhs.gov/hipaa/for-professionals/special-topics/de-identification/index.html | N52: REGULATION | O52: Explicitly protected identifier | P52: MEDIUM
A53: Patient Registration / Referral | B53: Intake and registration of a new patient, or referral of a patient between providers. | C53: Date of Birth | D53: Date of Birth | E53: Direct Identifier | F53: PII | G53: MUST_HAVE | H53: HIGH | I53: HIPAA Safe Harbor identifier; strengthens patient re-identification when combined with other fields. | J53: HIPAA Privacy Rule | K53: 45 CFR 164.514(b)(2) — Safe Harbor identifier list | L53: United States — HIPAA covered entities & business associates | M53: https://www.hhs.gov/hipaa/for-professionals/special-topics/de-identification/index.html | N53: REGULATION | O53: Explicitly protected identifier | P53: MEDIUM
A54: Patient Registration / Referral | B54: Intake and registration of a new patient, or referral of a patient between providers. | C54: Street / Mailing Address | D54: Street / Mailing Address | E54: Direct Identifier | F54: PII | G54: MUST_HAVE | H54: HIGH | I54: HIPAA Safe Harbor identifier; discloses where a patient lives, raising both privacy and physical-safety risk. | J54: HIPAA Privacy Rule | K54: 45 CFR 164.514(b)(2) — Safe Harbor identifier list | L54: United States — HIPAA covered entities & business associates | M54: https://www.hhs.gov/hipaa/for-professionals/special-topics/de-identification/index.html | N54: REGULATION | O54: Explicitly protected identifier | P54: MEDIUM
A55: Patient Registration / Referral | B55: Intake and registration of a new patient, or referral of a patient between providers. | C55: Phone Number | D55: Phone Number | E55: Direct Identifier | F55: PII | G55: MUST_HAVE | H55: MEDIUM | I55: HIPAA Safe Harbor identifier; enables phishing/social engineering against a patient. | J55: HIPAA Privacy Rule | K55: 45 CFR 164.514(b)(2) — Safe Harbor identifier list | L55: United States — HIPAA covered entities & business associates | M55: https://www.hhs.gov/hipaa/for-professionals/special-topics/de-identification/index.html | N55: REGULATION | O55: Explicitly protected identifier | P55: MEDIUM
A56: Patient Registration / Referral | B56: Intake and registration of a new patient, or referral of a patient between providers. | C56: Email Address | D56: Email Address | E56: Direct Identifier | F56: PII | G56: MUST_HAVE | H56: MEDIUM | I56: HIPAA Safe Harbor identifier; a credential-adjacent identifier usable for phishing tied to health context. | J56: HIPAA Privacy Rule | K56: 45 CFR 164.514(b)(2) — Safe Harbor identifier list | L56: United States — HIPAA covered entities & business associates | M56: https://www.hhs.gov/hipaa/for-professionals/special-topics/de-identification/index.html | N56: REGULATION | O56: Explicitly protected identifier | P56: MEDIUM
A57: Patient Registration / Referral | B57: Intake and registration of a new patient, or referral of a patient between providers. | C57: Social Security Number (SSN) | D57: Social Security Number (SSN) | E57: Government Identifier | F57: PII | G57: MUST_HAVE | H57: CRITICAL | I57: Identity theft, account fraud, impersonation, and long-term privacy harm — a US SSN cannot practically be reissued. | J57: NIST SP 800-122 / HIPAA Privacy Rule (in health context) | K57: SP 800-122 §2.1 — high-impact PII example; 45 CFR 164.514(b)(2)(I) if in a health record | L57: United States | M57: https://csrc.nist.gov/pubs/sp/800/122/final | N57: REGULATION | O57: Government identifier | P57: HIGH
A58: Patient Registration / Referral | B58: Intake and registration of a new patient, or referral of a patient between providers. | C58: Medical Record Number (MRN) | D58: Medical Record Number (MRN) | E58: Direct Identifier | F58: PHI | G58: MUST_HAVE | H58: CRITICAL | I58: Directly links an individual to their entire clinical history; enables medical-identity theft and insurance fraud. | J58: HIPAA Privacy Rule | K58: 45 CFR 164.514(b)(2)(I) — Medical record numbers | L58: United States — HIPAA covered entities | M58: https://www.hhs.gov/hipaa/for-professionals/special-topics/de-identification/index.html | N58: REGULATION | O58: PHI / health information | P58: HIGH
A59: Patient Registration / Referral | B59: Intake and registration of a new patient, or referral of a patient between providers. | C59: Health Insurance Policy Number | D59: Health Insurance Policy Number | E59: Direct Identifier | F59: PHI | G59: MUST_HAVE | H59: HIGH | I59: Enables fraudulent insurance claims and unauthorized access to coverage details. | J59: HIPAA Privacy Rule | K59: 45 CFR 164.514(b)(2)(I) — Health plan beneficiary numbers | L59: United States — HIPAA covered entities | M59: https://www.hhs.gov/hipaa/for-professionals/special-topics/de-identification/index.html | N59: REGULATION | O59: PHI / health information | P59: HIGH
A60: Patient Registration / Referral | B60: Intake and registration of a new patient, or referral of a patient between providers. | C60: Treating Provider Name / NPI Number | D60: Treating Provider Name / NPI Number | E60: Direct Identifier | F60: PHI | G60: NICE_TO_HAVE | H60: MEDIUM | I60: Discloses the treating clinician; can support social engineering against the practice, lower risk to the patient directly. | J60: HIPAA Privacy Rule | K60: 45 CFR 164.514(b)(2) — related identifiers | L60: United States — HIPAA covered entities | M60: https://www.hhs.gov/hipaa/for-professionals/special-topics/de-identification/index.html | N60: REGULATION | O60: PHI / health information | P60: MEDIUM
A61: Patient Registration / Referral | B61: Intake and registration of a new patient, or referral of a patient between providers. | C61: Signature | D61: Signature | E61: Direct Identifier | F61: PII | G61: NICE_TO_HAVE | H61: MEDIUM | I61: Enables forgery of authorization for treatment or disclosure. | J61: HIPAA Privacy Rule | K61: 45 CFR 164.514(b)(2) — Safe Harbor identifier list | L61: United States — HIPAA covered entities & business associates | M61: https://www.hhs.gov/hipaa/for-professionals/special-topics/de-identification/index.html | N61: REGULATION | O61: Explicitly protected identifier | P61: MEDIUM
A62: Explanation of Benefits (EOB) / Medical Claim | B62: Submission and adjudication of a claim for reimbursement of healthcare services. Encompasses both the Explanation of Benefits (EOB) issued to a member after a claim is processed and the underlying medical/health-insurance claim submission itself. | C62: Full Name / Person Name | D62: Full Name / Person Name | E62: Direct Identifier | F62: PII | G62: MUST_HAVE | H62: CRITICAL | I62: Re-identifies an individual's health record; enables medical-identity theft and targeted harassment. | J62: HIPAA Privacy Rule | K62: 45 CFR 164.514(b)(2) — Safe Harbor identifier list | L62: United States — HIPAA covered entities & business associates | M62: https://www.hhs.gov/hipaa/for-professionals/special-topics/de-identification/index.html | N62: REGULATION | O62: Explicitly protected identifier | P62: MEDIUM
...

Sheet Document_Summary
A1: Document Type | B1: Business Workflow | C1: Primary Regulations | D1: Relevant Policies | E1: Must-Have Entity Count | F1: Nice-to-Have Entity Count | G1: Drop Entity Count | H1: Critical-Risk Entity Count | I1: High-Risk Entity Count | J1: Main Threats | K1: Notes
A2: Medical Record / Clinical Note | B2: Ongoing clinical documentation of a patient's encounters, diagnoses, and treatment to support continuity of care. | C2: HIPAA Privacy Rule | D2: Company policy evidence not supplied. | E2: =COUNTIFS(Master_Entity_Policy!$A$2:$A$287,$A2,Master_Entity_Policy!$G$2:$G$287,"MUST_HAVE") -> 9 | F2: =COUNTIFS(Master_Entity_Policy!$A$2:$A$287,$A2,Master_Entity_Policy!$G$2:$G$287,"NICE_TO_HAVE") -> 6 | G2: =COUNTIFS(Master_Entity_Policy!$A$2:$A$287,$A2,Master_Entity_Policy!$G$2:$G$287,"DROP") -> 0 | H2: =COUNTIFS(Master_Entity_Policy!$A$2:$A$287,$A2,Master_Entity_Policy!$H$2:$H$287,"CRITICAL") -> 4 | I2: =COUNTIFS(Master_Entity_Policy!$A$2:$A$287,$A2,Master_Entity_Policy!$H$2:$H$287,"HIGH") -> 3 | J2: Can reveal a sensitive condition by inference (e.g., psychiatric, HIV, oncology drugs); enables prescription fraud.; Directly links an individual to their entire clinical history; enables medical-identity theft and insurance fraud.; Discloses the treating clinician; can support social engineering against the practice, lower risk to the patient directly.; Discloses treatment history; can imply a condition (re-identification risk) and support insurance fraud.; Discrimination, stigmatization, employment/insurance harm, and medical-privacy harm if disclosed. | K2: See Master_Entity_Policy for full entity-level detail.
A3: Lab Report / Pathology Report | B3: Laboratory or pathology testing and result reporting to support diagnosis and treatment decisions. | C3: HIPAA Privacy Rule | D3: Company policy evidence not supplied. | E3: =COUNTIFS(Master_Entity_Policy!$A$2:$A$287,$A3,Master_Entity_Policy!$G$2:$G$287,"MUST_HAVE") -> 5 | F3: =COUNTIFS(Master_Entity_Policy!$A$2:$A$287,$A3,Master_Entity_Policy!$G$2:$G$287,"NICE_TO_HAVE") -> 2 | G3: =COUNTIFS(Master_Entity_Policy!$A$2:$A$287,$A3,Master_Entity_Policy!$G$2:$G$287,"DROP") -> 1 | H3: =COUNTIFS(Master_Entity_Policy!$A$2:$A$287,$A3,Master_Entity_Policy!$H$2:$H$287,"CRITICAL") -> 3 | I3: =COUNTIFS(Master_Entity_Policy!$A$2:$A$287,$A3,Master_Entity_Policy!$H$2:$H$287,"HIGH") -> 1 | J3: Directly links an individual to their entire clinical history; enables medical-identity theft and insurance fraud.; Discloses physiological/health status; moderate standalone risk, higher when linked to identity.; Discloses the treating clinician; can support social engineering against the practice, lower risk to the patient directly.; Discrimination, stigmatization, employment/insurance harm, and medical-privacy harm if disclosed.; Enables re-identification when correlated with public event data (e.g., accident reports); listed HIPAA identifier. | K3: See Master_Entity_Policy for full entity-level detail.
A4: Prescription | B4: Prescribing and dispensing of medication to a patient. | C4: HIPAA Privacy Rule | D4: Company policy evidence not supplied. | E4: =COUNTIFS(Master_Entity_Policy!$A$2:$A$287,$A4,Master_Entity_Policy!$G$2:$G$287,"MUST_HAVE") -> 6 | F4: =COUNTIFS(Master_Entity_Policy!$A$2:$A$287,$A4,Master_Entity_Policy!$G$2:$G$287,"NICE_TO_HAVE") -> 2 | G4: =COUNTIFS(Master_Entity_Policy!$A$2:$A$287,$A4,Master_Entity_Policy!$G$2:$G$287,"DROP") -> 0 | H4: =COUNTIFS(Master_Entity_Policy!$A$2:$A$287,$A4,Master_Entity_Policy!$H$2:$H$287,"CRITICAL") -> 2 | I4: =COUNTIFS(Master_Entity_Policy!$A$2:$A$287,$A4,Master_Entity_Policy!$H$2:$H$287,"HIGH") -> 4 | J4: Can reveal a sensitive condition by inference (e.g., psychiatric, HIV, oncology drugs); enables prescription fraud.; Directly links an individual to their entire clinical history; enables medical-identity theft and insurance fraud.; Discloses the treating clinician; can support social engineering against the practice, lower risk to the patient directly.; Enables forgery of authorization for treatment or disclosure.; Enables fraudulent insurance claims and unauthorized access to coverage details. | K4: See Master_Entity_Policy for full entity-level detail.
A5: Discharge Summary | B5: Summary of a patient's hospital stay, treatment, and follow-up plan at the point of discharge. | C5: HIPAA Privacy Rule | D5: Company policy evidence not supplied. | E5: =COUNTIFS(Master_Entity_Policy!$A$2:$A$287,$A5,Master_Entity_Policy!$G$2:$G$287,"MUST_HAVE") -> 7 | F5: =COUNTIFS(Master_Entity_Policy!$A$2:$A$287,$A5,Master_Entity_Policy!$G$2:$G$287,"NICE_TO_HAVE") -> 3 | G5: =COUNTIFS(Master_Entity_Policy!$A$2:$A$287,$A5,Master_Entity_Policy!$G$2:$G$287,"DROP") -> 0 | H5: =COUNTIFS(Master_Entity_Policy!$A$2:$A$287,$A5,Master_Entity_Policy!$H$2:$H$287,"CRITICAL") -> 4 | I5: =COUNTIFS(Master_Entity_Policy!$A$2:$A$287,$A5,Master_Entity_Policy!$H$2:$H$287,"HIGH") -> 2 | J5: Can reveal a sensitive condition by inference (e.g., psychiatric, HIV, oncology drugs); enables prescription fraud.; Directly links an individual to their entire clinical history; enables medical-identity theft and insurance fraud.; Discloses the treating clinician; can support social engineering against the practice, lower risk to the patient directly.; Discloses treatment history; can imply a condition (re-identification risk) and support insurance fraud.; Discrimination, stigmatization, employment/insurance harm, and medical-privacy harm if disclosed. | K5: See Master_Entity_Policy for full entity-level detail.
A6: Imaging / Radiology Report | B6: Interpretation and reporting of diagnostic imaging studies (X-ray, CT, MRI, ultrasound). | C6: HIPAA Privacy Rule | D6: Company policy evidence not supplied. | E6: =COUNTIFS(Master_Entity_Policy!$A$2:$A$287,$A6,Master_Entity_Policy!$G$2:$G$287,"MUST_HAVE") -> 5 | F6: =COUNTIFS(Master_Entity_Policy!$A$2:$A$287,$A6,Master_Entity_Policy!$G$2:$G$287,"NICE_TO_HAVE") -> 2 | G6: =COUNTIFS(Master_Entity_Policy!$A$2:$A$287,$A6,Master_Entity_Policy!$G$2:$G$287,"DROP") -> 2 | H6: =COUNTIFS(Master_Entity_Policy!$A$2:$A$287,$A6,Master_Entity_Policy!$H$2:$H$287,"CRITICAL") -> 3 | I6: =COUNTIFS(Master_Entity_Policy!$A$2:$A$287,$A6,Master_Entity_Policy!$H$2:$H$287,"HIGH") -> 1 | J6: Directly links an individual to their entire clinical history; enables medical-identity theft and insurance fraud.; Discloses the treating clinician; can support social engineering against the practice, lower risk to the patient directly.; Discrimination, stigmatization, employment/insurance harm, and medical-privacy harm if disclosed.; Enables re-identification when correlated with public event data (e.g., accident reports); listed HIPAA identifier.; HIPAA Safe Harbor identifier; strengthens patient re-identification when combined with other fields. | K6: See Master_Entity_Policy for full entity-level detail.
A7: Patient Registration / Referral | B7: Intake and registration of a new patient, or referral of a patient between providers. | C7: HIPAA Privacy Rule; NIST SP 800-122 | D7: Company policy evidence not supplied. | E7: =COUNTIFS(Master_Entity_Policy!$A$2:$A$287,$A7,Master_Entity_Policy!$G$2:$G$287,"MUST_HAVE") -> 8 | F7: =COUNTIFS(Master_Entity_Policy!$A$2:$A$287,$A7,Master_Entity_Policy!$G$2:$G$287,"NICE_TO_HAVE") -> 2 | G7: =COUNTIFS(Master_Entity_Policy!$A$2:$A$287,$A7,Master_Entity_Policy!$G$2:$G$287,"DROP") -> 0 | H7: =COUNTIFS(Master_Entity_Policy!$A$2:$A$287,$A7,Master_Entity_Policy!$H$2:$H$287,"CRITICAL") -> 3 | I7: =COUNTIFS(Master_Entity_Policy!$A$2:$A$287,$A7,Master_Entity_Policy!$H$2:$H$287,"HIGH") -> 3 | J7: Directly links an individual to their entire clinical history; enables medical-identity theft and insurance fraud.; Discloses the treating clinician; can support social engineering against the practice, lower risk to the patient directly.; Enables forgery of authorization for treatment or disclosure.; Enables fraudulent insurance claims and unauthorized access to coverage details.; HIPAA Safe Harbor identifier; a credential-adjacent identifier usable for phishing tied to health context. | K7: See Master_Entity_Policy for full entity-level detail.
A8: Explanation of Benefits (EOB) / Medical Claim | B8: Submission and adjudication of a claim for reimbursement of healthcare services. Encompasses both the Explanation of Benefits (EOB) issued to a member after a claim is processed and the underlying medical/health-insurance claim submission itself. | C8: HIPAA Privacy Rule; NIST SP 800-122 | D8: Company policy evidence not supplied. | E8: =COUNTIFS(Master_Entity_Policy!$A$2:$A$287,$A8,Master_Entity_Policy!$G$2:$G$287,"MUST_HAVE") -> 10 | F8: =COUNTIFS(Master_Entity_Policy!$A$2:$A$287,$A8,Master_Entity_Policy!$G$2:$G$287,"NICE_TO_HAVE") -> 3 | G8: =COUNTIFS(Master_Entity_Policy!$A$2:$A$287,$A8,Master_Entity_Policy!$G$2:$G$287,"DROP") -> 0 | H8: =COUNTIFS(Master_Entity_Policy!$A$2:$A$287,$A8,Master_Entity_Policy!$H$2:$H$287,"CRITICAL") -> 4 | I8: =COUNTIFS(Master_Entity_Policy!$A$2:$A$287,$A8,Master_Entity_Policy!$H$2:$H$287,"HIGH") -> 4 | J8: Directly links an individual to their entire clinical history; enables medical-identity theft and insurance fraud.; Discloses the treating clinician; can support social engineering against the practice, lower risk to the patient directly.; Discloses treatment history; can imply a condition (re-identification risk) and support insurance fraud.; Discrimination, stigmatization, employment/insurance harm, and medical-privacy harm if disclosed.; Enables fraudulent insurance claims and unauthorized access to coverage details. | K8: See Master_Entity_Policy for full entity-level detail.
A9: Summary of Benefits and Coverage (SBC) | B9: Standardized, insurer/plan-produced disclosure (required in the U.S. group/individual health insurance market) summarizing a plan's benefits, cost-sharing, and coverage examples so a consumer/employee can compare plans; frequently distributed as a template, but sometimes issued as a personalized copy addressed to a specific enrollee. | C9: FTC Safeguards Rule; HIPAA Privacy Rule | D9: Company policy evidence not supplied. | E9: =COUNTIFS(Master_Entity_Policy!$A$2:$A$287,$A9,Master_Entity_Policy!$G$2:$G$287,"MUST_HAVE") -> 1 | F9: =COUNTIFS(Master_Entity_Policy!$A$2:$A$287,$A9,Master_Entity_Policy!$G$2:$G$287,"NICE_TO_HAVE") -> 3 | G9: =COUNTIFS(Master_Entity_Policy!$A$2:$A$287,$A9,Master_Entity_Policy!$G$2:$G$287,"DROP") -> 4 | H9: =COUNTIFS(Master_Entity_Policy!$A$2:$A$287,$A9,Master_Entity_Policy!$H$2:$H$287,"CRITICAL") -> 0 | I9: =COUNTIFS(Master_Entity_Policy!$A$2:$A$287,$A9,Master_Entity_Policy!$H$2:$H$287,"HIGH") -> 1 | J9: Identifies the employer/plan group rather than the individual directly; useful corroborating context but weaker re-identification value on its own.; Links the individual to a specific health plan and, indirectly, to their health-plan enrollment status.; Reveals an individual's personal healthcare spending obligation; sensitive but lower breach impact than an account or card number.; Uniquely identifies a specific enrollee within a health plan; enables medical-identity theft and unauthorized benefits inquiries. | K9: See Master_Entity_Policy for full entity-level detail.
A10: Health Insurance Policy / Benefits Document | B10: A member's individual policy, certificate of coverage, or benefits-summary document issued by a health plan describing that specific enrollee's (and dependents') coverage, identifiers, and billing arrangement — distinct from the generic, non-personalized SBC template. | C10: FTC Safeguards Rule; HIPAA Privacy Rule; NIST SP 800-122 | D10: Company policy evidence not supplied. | E10: =COUNTIFS(Master_Entity_Policy!$A$2:$A$287,$A10,Master_Entity_Policy!$G$2:$G$287,"MUST_HAVE") -> 8 | F10: =COUNTIFS(Master_Entity_Policy!$A$2:$A$287,$A10,Master_Entity_Policy!$G$2:$G$287,"NICE_TO_HAVE") -> 2 | G10: =COUNTIFS(Master_Entity_Policy!$A$2:$A$287,$A10,Master_Entity_Policy!$G$2:$G$287,"DROP") -> 2 | H10: =COUNTIFS(Master_Entity_Policy!$A$2:$A$287,$A10,Master_Entity_Policy!$H$2:$H$287,"CRITICAL") -> 2 | I10: =COUNTIFS(Master_Entity_Policy!$A$2:$A$287,$A10,Master_Entity_Policy!$H$2:$H$287,"HIGH") -> 5 | J10: Combined with name, enables identity verification bypass and medical-identity theft.; Direct financial-fraud and account-takeover risk if premium auto-pay banking details are exposed.; Directly identifies the individual whose coverage and health-plan enrollment the document describes; medical-identity theft and targeted-fraud risk.; Enables physical-world location of the individual; HIPAA Safe Harbor geographic identifier.; Enables social engineering, phishing, and unwanted contact tied to a known health-plan enrollee. | K10: See Master_Entity_Policy for full entity-level detail.
A11: Medical Appointment / Appointment Reminder | B11: Scheduling confirmation or reminder (letter, SMS-derived transcript, email, or portal notice) sent to a patient ahead of a healthcare visit, identifying the patient, the visit, and often the clinic/department. | C11: HIPAA Privacy Rule | D11: Company policy evidence not supplied. | E11: =COUNTIFS(Master_Entity_Policy!$A$2:$A$287,$A11,Master_Entity_Policy!$G$2:$G$287,"MUST_HAVE") -> 5 | F11: =COUNTIFS(Master_Entity_Policy!$A$2:$A$287,$A11,Master_Entity_Policy!$G$2:$G$287,"NICE_TO_HAVE") -> 3 | G11: =COUNTIFS(Master_Entity_Policy!$A$2:$A$287,$A11,Master_Entity_Policy!$G$2:$G$287,"DROP") -> 2 | H11: =COUNTIFS(Master_Entity_Policy!$A$2:$A$287,$A11,Master_Entity_Policy!$H$2:$H$287,"CRITICAL") -> 3 | I11: =COUNTIFS(Master_Entity_Policy!$A$2:$A$287,$A11,Master_Entity_Policy!$H$2:$H$287,"HIGH") -> 1 | J11: A specialty/department name can itself disclose a sensitive health category (cancer, mental health, reproductive health, infectious disease) even without an explicit diagnosis being stated.; Corroborating identifier that, combined with a specialty, can reinforce inference of a sensitive condition; lower standalone risk than the patient's own identity.; Directly discloses a sensitive health condition or reason for care; discrimination and privacy harm if exposed.; Enables phishing and account-targeting; moderate standalone breach impact.; Enables social engineering/phishing and unwanted contact; also carries independent regulatory exposure for automated reminder calls/texts. | K11: See Master_Entity_Policy for full entity-level detail.
A12: Healthcare Data Breach Notification Letter | B12: Legally-mandated notification (HIPAA Breach Notification Rule / applicable state law) sent to an affected individual after unauthorized access, use, or disclosure of their PHI, describing what happened, what data was involved, and what remediation is offered. Must be evaluated as a healthcare/PHI document, not treated under generic-letter DROP defaults, because it typically restates the individual's own compromised PHI/PII inline. | C12: HIPAA Privacy Rule; NIST SP 800-122 | D12: Company policy evidence not supplied. | E12: =COUNTIFS(Master_Entity_Policy!$A$2:$A$287,$A12,Master_Entity_Policy!$G$2:$G$287,"MUST_HAVE") -> 7 | F12: =COUNTIFS(Master_Entity_Policy!$A$2:$A$287,$A12,Master_Entity_Policy!$G$2:$G$287,"NICE_TO_HAVE") -> 1 | G12: =COUNTIFS(Master_Entity_Policy!$A$2:$A$287,$A12,Master_Entity_Policy!$G$2:$G$287,"DROP") -> 3 | H12: =COUNTIFS(Master_Entity_Policy!$A$2:$A$287,$A12,Master_Entity_Policy!$H$2:$H$287,"CRITICAL") -> 4 | I12: =COUNTIFS(Master_Entity_Policy!$A$2:$A$287,$A12,Master_Entity_Policy!$H$2:$H$287,"HIGH") -> 3 | J12: A unique code tied to one specific recipient that grants enrollment in a remediation service; exposure enables an attacker to claim the victim's free credit-monitoring benefit or pivot into further identity fraud.; Directly identifies the breach victim; combined with the described breached data, enables medical-identity theft and targeted fraud against a known-vulnerable individual.; Enables physical-world location of a known breach victim.; Enables unauthorized benefits access; part of the inline breach-content description.; Functions as an inline inventory of exactly which sensitive elements about this individual were exposed; re-exposing this text is itself a secondary disclosure of the same sensitive facts. | K12: See Master_Entity_Policy for full entity-level detail.
A13: Bank Statement | B13: Periodic statement of account activity issued by a bank to an accountholder. | C13: FTC Safeguards Rule; FTC Safeguards Rule (GLBA); GDPR Art. 4; NIST SP 800-122 | D13: Company policy evidence not supplied. | E13: =COUNTIFS(Master_Entity_Policy!$A$2:$A$287,$A13,Master_Entity_Policy!$G$2:$G$287,"MUST_HAVE") -> 6 | F13: =COUNTIFS(Master_Entity_Policy!$A$2:$A$287,$A13,Master_Entity_Policy!$G$2:$G$287,"NICE_TO_HAVE") -> 2 | G13: =COUNTIFS(Master_Entity_Policy!$A$2:$A$287,$A13,Master_Entity_Policy!$G$2:$G$287,"DROP") -> 0 | H13: =COUNTIFS(Master_Entity_Policy!$A$2:$A$287,$A13,Master_Entity_Policy!$H$2:$H$287,"CRITICAL") -> 2 | I13: =COUNTIFS(Master_Entity_Policy!$A$2:$A$287,$A13,Master_Entity_Policy!$H$2:$H$287,"HIGH") -> 2 | J13: Discloses spending behavior/financial profile; privacy-relevant but not independently exploitable without account credentials.; Enables account-recovery social engineering and SIM-swap style fraud.; Enables fraudulent ACH/wire setup when combined with an account number; low risk in isolation.; Enables identity theft, account takeover, and social engineering when paired with account data.; Enables mail fraud, identity theft, and physical targeting when paired with financial data. | K13: See Master_Entity_Policy for full entity-level detail.
... A32: Email / Letter / General Form / Scanned Document | B32: General business or personal correspondence, forms, or scanned documents not otherwise classified. | C32: GDPR Art. 4 | D32: Company policy evidence not supplied. | E32: =COUNTIFS(Master_Entity_Policy!$A$2:$A$287,$A32,Master_Entity_Policy!$G$2:$G$287,"MUST_HAVE") -> 1 | F32: =COUNTIFS(Master_Entity_Policy!$A$2:$A$287,$A32,Master_Entity_Policy!$G$2:$G$287,"NICE_TO_HAVE") -> 4 | G32: =COUNTIFS(Master_Entity_Policy!$A$2:$A$287,$A32,Master_Entity_Policy!$G$2:$G$287,"DROP") -> 6 | H32: =COUNTIFS(Master_Entity_Policy!$A$2:$A$287,$A32,Master_Entity_Policy!$H$2:$H$287,"CRITICAL") -> 0 | I32: =COUNTIFS(Master_Entity_Policy!$A$2:$A$287,$A32,Master_Entity_Policy!$H$2:$H$287,"HIGH") -> 0 | J32: Basic identity exposure; risk rises sharply when combined with other identifiers.; Discloses residence; moderate risk on its own, higher when combined with a name.; Enables phishing, spam, and account-targeting.; Enables phishing, spam, and social engineering.; Low standalone risk; relevant mainly as forgery material in combination with other data. | K32: See Master_Entity_Policy for full entity-level detail.

Sheet Must_Have_Entities
A1: Document Type | B1: Entity | C1: Canonical Entity | D1: Category | E1: Risk Level | F1: Threat | G1: Regulation | H1: Policy | I1: Classification Basis | J1: Rationale | K1: Evidence URL
A2: Medical Record / Clinical Note | B2: Full Name / Person Name | C2: Full Name / Person Name | D2: Direct Identifier | E2: CRITICAL | F2: Re-identifies an individual's health record; enables medical-identity theft and targeted harassment. | G2: HIPAA Privacy Rule | H2: Company policy evidence not supplied. | I2: REGULATION | J2: Primary direct identifier under HIPAA Safe Harbor; combined with clinical data it converts de-identified content back into PHI. | K2: https://www.hhs.gov/hipaa/for-professionals/special-topics/de-identification/index.html
A3: Medical Record / Clinical Note | B3: Date of Birth | C3: Date of Birth | D3: Direct Identifier | E3: HIGH | F3: HIPAA Safe Harbor identifier; strengthens patient re-identification when combined with other fields. | G3: HIPAA Privacy Rule | H3: Company policy evidence not supplied. | I3: REGULATION | J3: Listed identifier requiring removal for de-identified data sets. | K3: https://www.hhs.gov/hipaa/for-professionals/special-topics/de-identification/index.html
A4: Medical Record / Clinical Note | B4: Medical Record Number (MRN) | C4: Medical Record Number (MRN) | D4: Direct Identifier | E4: CRITICAL | F4: Directly links an individual to their entire clinical history; enables medical-identity theft and insurance fraud. | G4: HIPAA Privacy Rule | H4: Company policy evidence not supplied. | I4: REGULATION | J4: Explicitly enumerated in the HIPAA Safe Harbor identifier list. | K4: https://www.hhs.gov/hipaa/for-professionals/special-topics/de-identification/index.html
A5: Medical Record / Clinical Note | B5: Street / Mailing Address | C5: Street / Mailing Address | D5: Direct Identifier | E5: HIGH | F5: HIPAA Safe Harbor identifier; discloses where a patient lives, raising both privacy and physical-safety risk. | G5: HIPAA Privacy Rule | H5: Company policy evidence not supplied. | I5: REGULATION | J5: Listed identifier requiring removal for de-identified data sets. | K5: https://www.hhs.gov/hipaa/for-professionals/special-topics/de-identification/index.html
A6: Medical Record / Clinical Note | B6: Phone Number | C6: Phone Number | D6: Direct Identifier | E6: MEDIUM | F6: HIPAA Safe Harbor identifier; enables phishing/social engineering against a patient. | G6: HIPAA Privacy Rule | H6: Company policy evidence not supplied. | I6: REGULATION | J6: Listed identifier requiring removal for de-identified data sets. | K6: https://www.hhs.gov/hipaa/for-professionals/special-topics/de-identification/index.html
A7: Medical Record / Clinical Note | B7: Diagnosis / Medical Condition | C7: Diagnosis / Medical Condition | D7: Health/Clinical Data | E7: CRITICAL | F7: Discrimination, stigmatization, employment/insurance harm, and medical-privacy harm if disclosed. | G7: HIPAA Privacy Rule | H7: Company policy evidence not supplied. | I7: REGULATION | J7: Core content-based PHI element; discloses the individual's health status. | K7: https://www.hhs.gov/hipaa/for-professionals/special-topics/de-identification/index.html
A8: Medical Record / Clinical Note | B8: Medication / Prescription Detail | C8: Medication / Prescription Detail | D8: Health/Clinical Data | E8: HIGH | F8: Can reveal a sensitive condition by inference (e.g., psychiatric, HIV, oncology drugs); enables prescription fraud. | G8: HIPAA Privacy Rule | H8: Company policy evidence not supplied. | I8: REGULATION | J8: Content-based PHI with meaningful re-identification and fraud risk (controlled substances especially). | K8: https://www.hhs.gov/hipaa/for-professionals/special-topics/de-identification/index.html
A9: Medical Record / Clinical Note | B9: Clinical Notes / Narrative | C9: Clinical Notes / Narrative | D9: Health/Clinical Data | E9: CRITICAL | F9: Free text frequently contains multiple PHI elements at once (identity + diagnosis + history); high aggregate breach impact. | G9: HIPAA Privacy Rule | H9: Company policy evidence not supplied. | I9: REGULATION | J9: Narrative text is the highest-density PHI surface in a medical record. | K9: https://www.hhs.gov/hipaa/for-professionals/special-topics/de-identification/index.html
A10: Medical Record / Clinical Note | B10: Admission / Discharge / Service Date | C10: Admission / Discharge / Service Date | D10: Direct Identifier | E10: MEDIUM | F10: Enables re-identification when correlated with public event data (e.g., accident reports); listed HIPAA identifier. | G10: HIPAA Privacy Rule | H10: Company policy evidence not supplied. | I10: REGULATION | J10: Explicitly listed in the HIPAA Safe Harbor identifier set (dates directly related to an individual, other than year). | K10: https://www.hhs.gov/hipaa/for-professionals/special-topics/de-identification/index.html
A11: Lab Report / Pathology Report | B11: Full Name / Person Name | C11: Full Name / Person Name | D11: Direct Identifier | E11: CRITICAL | F11: Re-identifies an individual's health record; enables medical-identity theft and targeted harassment. | G11: HIPAA Privacy Rule | H11: Company policy evidence not supplied. | I11: REGULATION | J11: Primary direct identifier under HIPAA Safe Harbor; combined with clinical data it converts de-identified content back into PHI. | K11: https://www.hhs.gov/hipaa/for-professionals/special-topics/de-identification/index.html
A12: Lab Report / Pathology Report | B12: Date of Birth | C12: Date of Birth | D12: Direct Identifier | E12: HIGH | F12: HIPAA Safe Harbor identifier; strengthens patient re-identification when combined with other fields. | G12: HIPAA Privacy Rule | H12: Company policy evidence not supplied. | I12: REGULATION | J12: Listed identifier requiring removal for de-identified data sets. | K12: https://www.hhs.gov/hipaa/for-professionals/special-topics/de-identification/index.html
... A173: Email / Letter / General Form / Scanned Document | B173: Full Name / Person Name | C173: Full Name / Person Name | D173: Direct Identifier | E173: MEDIUM | F173: Basic identity exposure; risk rises sharply when combined with other identifiers. | G173: GDPR Art. 4 / India DPDP Act, 2023 | H173: Company policy evidence not supplied. | I173: REGULATION | J173: Foundational direct identifier present in most general correspondence. | K173: https://eur-lex.europa.eu/eli/reg/2016/679/art_4/par_1/oj

Sheet Nice_To_Have_Entities
A1: Document Type | B1: Entity | C1: Canonical Entity | D1: Category | E1: Risk Level | F1: Threat | G1: Regulation | H1: Policy | I1: Classification Basis | J1: Rationale | K1: Evidence URL
A2: Medical Record / Clinical Note | B2: Procedure Code / Description | C2: Procedure Code / Description | D2: Health/Clinical Data | E2: MEDIUM | F2: Discloses treatment history; can imply a condition (re-identification risk) and support insurance fraud. | G2: HIPAA Privacy Rule | H2: Company policy evidence not supplied. | I2: REGULATION | J2: Content-based PHI; lower standalone severity than an explicit diagnosis but still identifies care received. | K2: https://www.hhs.gov/hipaa/for-professionals/special-topics/de-identification/index.html
A3: Medical Record / Clinical Note | B3: Allergy Information | C3: Allergy Information | D3: Health/Clinical Data | E3: MEDIUM | F3: Reveals health information; misuse risk lower than diagnosis but still privacy-sensitive. | G3: HIPAA Privacy Rule | H3: Company policy evidence not supplied. | I3: REGULATION | J3: Content-based PHI, secondary to primary diagnosis/medication risk. | K3: https://www.hhs.gov/hipaa/for-professionals/special-topics/de-identification/index.html
A4: Medical Record / Clinical Note | B4: Treating Provider Name / NPI Number | C4: Treating Provider Name / NPI Number | D4: Direct Identifier | E4: MEDIUM | F4: Discloses the treating clinician; can support social engineering against the practice, lower risk to the patient directly. | G4: HIPAA Privacy Rule | H4: Company policy evidence not supplied. | I4: REGULATION | J4: NPI is a public NPPES-registry identifier for the provider, not the patient, so patient-privacy impact is indirect; still useful context for record completeness. | K4: https://www.hhs.gov/hipaa/for-professionals/special-topics/de-identification/index.html
A5: Medical Record / Clinical Note | B5: Geographic Subdivision Smaller Than State (ZIP) | C5: Geographic Subdivision Smaller Than State (ZIP) | D5: Direct Identifier | E5: LOW | F5: Low standalone risk; becomes meaningful re-identification risk only in small-population geographies or combined with other quasi-identifiers. | G5: HIPAA Privacy Rule | H5: Company policy evidence not supplied. | I5: REGULATION | J5: Explicitly listed in HIPAA Safe Harbor, with a carve-out allowing the first three digits of a ZIP code if the associated population exceeds 20,000. Relevant primarily for de-identification workflows. | K5: https://www.hhs.gov/hipaa/for-professionals/special-topics/de-identification/index.html
A6: Medical Record / Clinical Note | B6: Age Over 89 (HIPAA Safe Harbor Threshold) | C6: Age Over 89 (HIPAA Safe Harbor Threshold) | D6: Direct Identifier | E6: LOW | F6: Low standalone risk; HIPAA requires ages over 89 to be aggregated into a single category to prevent re-identification of a small cohort. | G6: HIPAA Privacy Rule | H6: Company policy evidence not supplied. | I6: REGULATION | J6: Explicit Safe Harbor rule for the narrow band of very-elderly patients. General age fields for patients 89 and under are lower priority and can typically be treated as DROP unless bundled with DOB. | K6: https://www.hhs.gov/hipaa/for-professionals/special-topics/de-identification/index.html
A7: Medical Record / Clinical Note | B7: Signature | C7: Signature | D7: Direct Identifier | E7: MEDIUM | F7: Enables forgery of authorization for treatment or disclosure. | G7: HIPAA Privacy Rule | H7: Company policy evidence not supplied. | I7: REGULATION | J7: Evidence of patient/provider authorization; moderate standalone breach impact. | K7: https://www.hhs.gov/hipaa/for-professionals/special-topics/de-identification/index.html
A8: Lab Report / Pathology Report | B8: Lab Test Result / Value | C8: Lab Test Result / Value | D8: Health/Clinical Data | E8: MEDIUM | F8: Discloses physiological/health status; moderate standalone risk, higher when linked to identity. | G8: HIPAA Privacy Rule | H8: Company policy evidence not supplied. | I8: REGULATION | J8: Content-based PHI; classified NICE_TO_HAVE because raw numeric values carry less direct re-identification power than the diagnosis they support. | K8: https://www.hhs.gov/hipaa/for-professionals/special-topics/de-identification/index.html
A9: Lab Report / Pathology Report | B9: Treating Provider Name / NPI Number | C9: Treating Provider Name / NPI Number | D9: Direct Identifier | E9: MEDIUM | F9: Discloses the treating clinician; can support social engineering against the practice, lower risk to the patient directly. | G9: HIPAA Privacy Rule | H9: Company policy evidence not supplied. | I9: REGULATION | J9: NPI is a public NPPES-registry identifier for the provider, not the patient, so patient-privacy impact is indirect; still useful context for record completeness. | K9: https://www.hhs.gov/hipaa/for-professionals/special-topics/de-identification/index.html
A10: Prescription | B10: Treating Provider Name / NPI Number | C10: Treating Provider Name / NPI Number | D10: Direct Identifier | E10: MEDIUM | F10: Discloses the treating clinician; can support social engineering against the practice, lower risk to the patient directly. | G10: HIPAA Privacy Rule | H10: Company policy evidence not supplied. | I10: REGULATION | J10: NPI is a public NPPES-registry identifier for the provider, not the patient, so patient-privacy impact is indirect; still useful context for record completeness. | K10: https://www.hhs.gov/hipaa/for-professionals/special-topics/de-identification/index.html
A11: Prescription | B11: Signature | C11: Signature | D11: Direct Identifier | E11: MEDIUM | F11: Enables forgery of authorization for treatment or disclosure. | G11: HIPAA Privacy Rule | H11: Company policy evidence not supplied. | I11: REGULATION | J11: Evidence of patient/provider authorization; moderate standalone breach impact. | K11: https://www.hhs.gov/hipaa/for-professionals/special-topics/de-identification/index.html
